<?xml version="1.0"?>
<!--
  Depot world: flat ground, one box obstacle, and the ars_bot differential
  drive AMR. The DiffDrive system consumes /cmd_vel; the JointStatePublisher
  system feeds the stack's own odometry (the plugin's built-in odometry is
  intentionally not bridged - state estimation is ars_core's job).
-->
<sdf version="1.9">
  <world name="depot">
    <physics name="default_physics" type="ode">
      <max_step_size>0.004</max_step_size>
      <real_time_factor>1.0</real_time_factor>
    </physics>
    <plugin filename="gz-sim-physics-system" name="gz::sim::systems::Physics"/>
    <plugin filename="gz-sim-user-commands-system" name="gz::sim::systems::UserCommands"/>
    <plugin filename="gz-sim-scene-broadcaster-system" name="gz::sim::systems::SceneBroadcaster"/>

    <light type="directional" name="sun">
      <cast_shadows>true</cast_shadows>
      <pose>0 0 10 0 0 0</pose>
      <diffuse>0.8 0.8 0.8 1</diffuse>
      <direction>-0.5 0.1 -0.9</direction>
    </light>

    <model name="ground_plane">
      <static>true</static>
      <link name="link">
        <collision name="collision">
          <geometry><plane><normal>0 0 1</normal><size>100 100</size></plane></geometry>
        </collision>
        <visual name="visual">
          <geometry><plane><normal>0 0 1</normal><size>100 100</size></plane></geometry>
          <material><ambient>0.7 0.7 0.7 1</ambient><diffuse>0.7 0.7 0.7 1</diffuse></material>
        </visual>
      </link>
    </model>

    <model name="crate">
      <static>true</static>
      <pose>2.0 1.0 0.25 0 0 0</pose>
      <link name="link">
        <collision name="collision">
          <geometry><box><size>0.5 0.5 0.5</size></box></geometry>
        </collision>
        <visual name="visual">
          <geometry><box><size>0.5 0.5 0.5</size></box></geometry>
          <material><ambient>0.6 0.4 0.2 1</ambient><diffuse>0.6 0.4 0.2 1</diffuse></material>
        </visual>
      </link>
    </model>

    <model name="ars_bot">
      <pose>0 0 0 0 0 0</pose>

      <link name="base_link">
        <pose>0 0 0.2 0 0 0</pose>
        <inertial>
          <mass>5.0</mass>
          <inertia>
            <ixx>0.05</ixx><iyy>0.12</iyy><izz>0.15</izz>
            <ixy>0</ixy><ixz>0</ixz><iyz>0</iyz>
          </inertia>
        </inertial>
        <collision name="collision">
          <geometry><box><size>0.6 0.3 0.15</size></box></geometry>
        </collision>
        <visual name="visual">
          <geometry><box><size>0.6 0.3 0.15</size></box></geometry>
          <material><ambient>0.1 0.3 0.8 1</ambient><diffuse>0.1 0.3 0.8 1</diffuse></material>
        </visual>
      </link>

      <link name="left_wheel">
        <pose>-0.15 0.25 0.1 -1.5707 0 0</pose>
        <inertial>
          <mass>0.5</mass>
          <inertia>
            <ixx>0.002</ixx><iyy>0.002</iyy><izz>0.0025</izz>
            <ixy>0</ixy><ixz>0</ixz><iyz>0</iyz>
          </inertia>
        </inertial>
        <collision name="collision">
          <geometry><cylinder><radius>0.1</radius><length>0.05</length></cylinder></geometry>
        </collision>
        <visual name="visual">
          <geometry><cylinder><radius>0.1</radius><length>0.05</length></cylinder></geometry>
          <material><ambient>0.1 0.1 0.1 1</ambient><diffuse>0.1 0.1 0.1 1</diffuse></material>
        </visual>
      </link>

      <link name="right_wheel">
        <pose>-0.15 -0.25 0.1 -1.5707 0 0</pose>
        <inertial>
          <mass>0.5</mass>
          <inertia>
            <ixx>0.002</ixx><iyy>0.002</iyy><izz>0.0025</izz>
            <ixy>0</ixy><ixz>0</ixz><iyz>0</iyz>
          </inertia>
        </inertial>
        <collision name="collision">
          <geometry><cylinder><radius>0.1</radius><length>0.05</length></cylinder></geometry>
        </collision>
        <visual name="visual">
          <geometry><cylinder><radius>0.1</radius><length>0.05</length></cylinder></geometry>
          <material><ambient>0.1 0.1 0.1 1</ambient><diffuse>0.1 0.1 0.1 1</diffuse></material>
        </visual>
      </link>

      <link name="caster">
        <pose>0.2 0 0.05 0 0 0</pose>
        <inertial>
          <mass>0.2</mass>
          <inertia>
            <ixx>0.0004</ixx><iyy>0.0004</iyy><izz>0.0004</izz>
            <ixy>0</ixy><ixz>0</ixz><iyz>0</iyz>
          </inertia>
        </inertial>
        <collision name="collision">
          <geometry><sphere><radius>0.05</radius></sphere></geometry>
          <surface>
            <friction><ode><mu>0.0</mu><mu2>0.0</mu2></ode></friction>
          </surface>
        </collision>
        <visual name="visual">
          <geometry><sphere><radius>0.05</radius></sphere></geometry>
          <material><ambient>0.3 0.3 0.3 1</ambient><diffuse>0.3 0.3 0.3 1</diffuse></material>
        </visual>
      </link>

      <joint name="left_wheel_joint" type="revolute">
        <parent>base_link</parent>
        <child>left_wheel</child>
        <axis>
          <xyz>0 0 1</xyz>
          <limit><lower>-1.79769e308</lower><upper>1.79769e308</upper></limit>
        </axis>
      </joint>

      <joint name="right_wheel_joint" type="revolute">
        <parent>base_link</parent>
        <child>right_wheel</child>
        <axis>
          <xyz>0 0 1</xyz>
          <limit><lower>-1.79769e308</lower><upper>1.79769e308</upper></limit>
        </axis>
      </joint>

      <joint name="caster_joint" type="ball">
        <parent>base_link</parent>
        <child>caster</child>
      </joint>

      <plugin filename="gz-sim-diff-drive-system" name="gz::sim::systems::DiffDrive">
        <left_joint>left_wheel_joint</left_joint>
        <right_joint>right_wheel_joint</right_joint>
        <wheel_separation>0.5</wheel_separation>
        <wheel_radius>0.1</wheel_radius>
        <topic>cmd_vel</topic>
        <max_linear_acceleration>1.0</max_linear_acceleration>
        <max_angular_acceleration>2.0</max_angular_acceleration>
      </plugin>

      <plugin filename="gz-sim-joint-state-publisher-system"
              name="gz::sim::systems::JointStatePublisher">
        <joint_name>left_wheel_joint</joint_name>
        <joint_name>right_wheel_joint</joint_name>
      </plugin>
    </model>
  </world>
</sdf>
